Workbook

Sheet DKI 1
F1: TARGET SALES FEBRUARI 2025
F2: BCO DKI 1
B4: DIVISI RAYON | C4: DIVISI INC | D4: STATUS SF | F4: KODE RAYON (div + level + rayon) | G4: LEVEL | H4: NAMA SALES FORCE | I4: TARGET IN VALUE | J4: TARGET IN UNIT (TW) | K4: TOTAL TARGET
A6: .
A7: . | B7: SPM | C7: SPM | D7: PS VACANT | F7: SPM JKB | G7: PS | H7: Ex. Rahmat Wahyudiono B.R. | I7: 50000000 | K7: =SUM(I7:J7) -> 50000000 | L7: UPDATE SF
A8: . | B8: SPM | C8: SPM | D8: PS TERISI | F8: SPM JKSP | G8: PS | H8: Titus Daniel Christian | I8: 270000000 | K8: =SUM(I8:J8) -> 270000000
A9: . | B9: SPM | C9: SPM | D9: PS VACANT | F9: SPM TGR | G9: PS | H9: Ex. Idad Sembada | I9: 50000000 | K9: =SUM(I9:J9) -> 50000000 | L9: UPDATE SF
A10: . | C10: SPM | D10: DM TERISI | F10: SPM DM DKI 1 | G10: DM | H10: ANDI JEN G PUTRA | I10: =SUM(I7:I9) -> 370000000 | J10: =SUM(J7:J9) -> 0 | K10: =SUM(I10:J10) -> 370000000
A11: .
A12: . | B12: PMT | C12: PMT | D12: PS VACANT | F12: PMT JKB | G12: PS | H12: Ex. Muhamad Zainul Umam | I12: 30000000 | K12: =SUM(I12:J12) -> 30000000
A13: . | B13: PMT | C13: PMT | D13: PS VACANT | F13: PMT JKSP | G13: PS | H13: Ex. Ilham Jufandi | I13: 50000000 | K13: =SUM(I13:J13) -> 50000000
A14: . | B14: PMT | C14: PMT | D14: PS TERISI | F14: PMT TGR | G14: PS | H14: Bari Raharjo | I14: 30000000 | K14: =SUM(I14:J14) -> 30000000
A15: . | C15: PMT | D15: DM VACANT | F15: PMT DM DKI 1 | G15: DM | H15: EX. SITI AISYAH E (vacum) | I15: 0 | J15: 0 | K15: =SUM(I15:J15) -> 0
A16: .
A17: . | B17: COMBO UTM-SPM-PMT | C17: UTM | D17: DM VACANT | F17: COMBO DM PNK (UTM-SPM-PMT) | G17: DM | H17: MR. X | I17: 65000000 | K17: =SUM(I17:J17) -> 65000000
A18: .
A19: . | C19: SPM | D19: RSM TERISI | F19: COMBO RSM JAKBAN 2 | G19: RSM | H19: WAHYU PURNOMO | I19: =I10+I12+I13+I14+I17 -> 545000000 | J19: =J10+J12+J13+J14+J17 -> 0 | K19: =SUM(I19:J19) -> 545000000
A20: .
A21: . | B21: UTM | C21: UTM | D21: PS TERISI | F21: UTM JKB | G21: PS | H21: Wahyu Restu Agung | I21: 135000000 | K21: =SUM(I21:J21) -> 135000000
A22: . | B22: UTM | C22: UTM | D22: PS VACANT | F22: UTM JKSP | G22: PS | H22: Ex. Hazreza Getarcita Atthoriq | I22: 255000000 | K22: =SUM(I22:J22) -> 255000000
A23: . | B23: UTM | C23: UTM | D23: PS VACANT | F23: UTM TGR 1 | G23: PS | H23: Ex. Arrayza Fautsar Aldamus | I23: 120000000 | K23: =SUM(I23:J23) -> 120000000
A24: . | B24: UTM | C24: UTM | D24: PS TERISI | F24: UTM TGR 2 | G24: PS | H24: Refa Aqmar Aulia | I24: 85000000 | K24: =SUM(I24:J24) -> 85000000 | L24: UPDATE SF
A25: . | C25: UTM | D25: DM TERISI | F25: UTM DM DKI 1 | G25: DM | H25: SITI AISYAH E | I25: =SUM(I21:I24) -> 595000000 | J25: =SUM(J21:J24) -> 0 | K25: =SUM(I25:J25) -> 595000000
A26: .
A27: . | B27: COMBO PRM-PNC | C27: PRM | D27: AM TERISI | F27: COMBO AM DKI 1 (PRM-PNC) | G27: AM | H27: ARI DONI | I27: 60000000 | J27: 349000000 | K27: =SUM(I27:J27) -> 409000000
A28: .
A29: . | C29: BCO | D29: BCO TERISI | F29: BCO DKI 1 | G29: BCO | H29: RIALDI AGUSTIAN | I29: =I19+I25+I27 -> 1200000000 | J29: =J19+J25+J27 -> 349000000 | K29: =SUM(I29:J29) -> 1549000000
F37: DIVISI RAYON | G37: JUMLAH RAYON | I37: TARGET
F38: UTM | G38: =COUNTIF($B$7:$B$29,"UTM") -> 4 | I38: =SUMIFS($K$7:$K$29,$B$7:$B$29,F38) -> 595000000
F39: SPM | G39: =COUNTIF($B$7:$B$29,"SPM") -> 3 | I39: =SUMIFS($K$7:$K$29,$B$7:$B$29,F39) -> 370000000
F40: PMT | G40: =COUNTIF($B$7:$B$29,"PMT") -> 3 | I40: =SUMIFS($K$7:$K$29,$B$7:$B$29,F40) -> 110000000
F41: PRM | G41: =COUNTIF($B$7:$B$29,"PRM") -> 0 | I41: =I27 -> 60000000
F42: COMBO UTM-SPM | G42: =COUNTIF($B$7:$B$29,"COMBO UTM-SPM") -> 0 | I42: =SUMIFS($K$7:$K$29,$B$7:$B$29,F42) -> 0
F43: COMBO UTM-SPM-PMT | G43: =COUNTIF($B$7:$B$29,"COMBO UTM-SPM-PMT") -> 1 | I43: =SUMIFS($K$7:$K$29,$B$7:$B$29,F43) -> 65000000
F44: COMBO UTM-SPM-PRM-PNC | G44: =COUNTIF($B$7:$B$29,"COMBO UTM-SPM-PRM-PNC") -> 0 | I44: =SUMIFS($K$7:$K$29,$B$7:$B$29,F44) -> 0
F45: COMBO PRM-PNC | G45: =COUNTIF($B$7:$B$29,"COMBO PRM-PNC") -> 1 | I45: 0
F46: COMBO ALL DIV | G46: =COUNTIF($B$7:$B$29,"COMBO ALL DIV") -> 0 | I46: =SUMIFS($K$7:$K$29,$B$7:$B$29,F46) -> 0
F47: PNC | G47: =COUNTIF($B$7:$B$29,"PNC") -> 0 | I47: =J27 -> 349000000
F48: TOTAL | G48: =SUM(G38:H47) -> 12 | I48: =SUM(I38:I47) -> 1549000000
F50: LEVEL | G50: TOTAL | H50: TERISI | I50: VACANT
...

Sheet DKI 2
F1: TARGET SALES FEBRUARI 2025
F2: BCO DKI 2
B4: DIVISI RAYON | C4: DIVISI INC | D4: STATUS SF | F4: KODE RAYON (div + level + rayon) | G4: LEVEL | H4: NAMA SALES FORCE | I4: TARGET IN VALUE | J4: TARGET IN UNIT (TW) | K4: TOTAL TARGET
A6: .
A7: . | B7: SPM | C7: SPM | D7: PS VACANT | F7: SPM JKTU | G7: PS | H7: Ex. Luthfi Harpatoni | I7: 237000000 | K7: =SUM(I7:J7) -> 237000000 | L7: UPDATE SF
A8: . | B8: SPM | C8: SPM | D8: PS TERISI | F8: SPM BKS | G8: PS | H8: Raphael Moses Tambunan | I8: 50500000 | K8: =SUM(I8:J8) -> 50500000
A9: . | B9: COMBO UTM-SPM | C9: UTM | D9: PS TERISI | F9: COMBO DPK (UTM-SPM) | G9: PS | H9: Wirawan Krishna Artedi | I9: 80000000 | K9: =SUM(I9:J9) -> 80000000
A10: . | C10: UTM | D10: DM TERISI | F10: COMBO DM JAKSIPOK | G10: DM | H10: AGUS SUNARTO | I10: =SUM(I7:I9) -> 367500000 | J10: =SUM(J7:J9) -> 0 | K10: =SUM(I10:J10) -> 367500000 | L10: UPDATE SF
A11: .
A12: . | B12: PMT | C12: PMT | D12: PS VACANT | F12: PMT JKTI | G12: PS | H12: Ex. Hendro Prawira Tobing | I12: 40000000 | K12: =SUM(I12:J12) -> 40000000
A13: . | B13: PMT | C13: PMT | D13: PS TERISI | F13: PMT BODE | G13: PS | H13: Abramsyah Ali Reza | I13: 20000000 | K13: =SUM(I13:J13) -> 20000000
A14: . | C14: PMT | D14: DM TERISI | F14: PMT DM DKI 2 | G14: DM | H14: AGUS SUNARTO | I14: =SUM(I12:I13) -> 60000000 | J14: =SUM(J12:J13) -> 0 | K14: =SUM(I14:J14) -> 60000000
A15: .
A16: . | B16: COMBO ALL DIV | C16: UTM | D16: DM VACANT | F16: COMBO DM BABEL (ALL DIV) | G16: DM | H16: MR. X | I16: 52500000 | K16: =SUM(I16:J16) -> 52500000
A17: .
A18: . | C18: SPM | D18: RSM TERISI | F18: COMBO RSM JAKSIBODE | G18: RSM | H18: ARIEF SETIAWAN | I18: =I10+I14+I16 -> 480000000 | J18: =J10+J14+J16 -> 0 | K18: =SUM(I18:J18) -> 480000000
A19: .
A20: . | B20: UTM | C20: UTM | D20: PS TERISI | F20: UTM JKTU | G20: PS | H20: Renita Anggraini | I20: 70000000 | K20: =SUM(I20:J20) -> 70000000
A21: . | B21: UTM | C21: UTM | D21: PS VACANT | F21: UTM BKS 1 | G21: PS | H21: Ex. Novi Andayani | I21: 150000000 | K21: =SUM(I21:J21) -> 150000000 | L21: UPDATE SF
A22: . | B22: UTM | C22: UTM | D22: PS TERISI | F22: UTM BKS 2 | G22: PS | H22: Andes Tiara Kusuma | I22: 80000000 | K22: =SUM(I22:J22) -> 80000000
A23: . | B23: COMBO UTM-SPM | C23: UTM | D23: PS TERISI | F23: COMBO BGR (UTM-SPM) | G23: PS | H23: Nur Annissa Dwisari | I23: 70000000 | K23: =SUM(I23:J23) -> 70000000
A24: . | B24: COMBO PRM-PNC | C24: PRM | D24: AE VACANT | F24: COMBO DKI 2 (PRM-PNC) | G24: AE | H24: Mr. X | I24: 100000000 | J24: 349000000 | K24: =SUM(I24:J24) -> 449000000
A25: . | C25: UTM | D25: DM TERISI | F25: COMBO DM JAKSIGOR | G25: DM | H25: TRI HANDOKO | I25: =SUM(I20:I24) -> 470000000 | J25: =SUM(J20:J24) -> 349000000 | K25: =SUM(I25:J25) -> 819000000
A26: .
A27: . | C27: BCO | D27: BCO TERISI | F27: BCO DKI 2 | G27: BCO | H27: M. IQBAL GAFFAR | I27: =I18+I25 -> 950000000 | J27: =J25 -> 349000000 | K27: =SUM(I27:J27) -> 1299000000
F35: DIVISI RAYON | G35: JUMLAH RAYON | I35: TARGET
F36: UTM | G36: =COUNTIF($B$20:$B$27,"UTM") -> 3 | I36: =SUMIFS($K$7:$K$27,$B$7:$B$27,F36) -> 300000000
F37: SPM | G37: =COUNTIF($B$20:$B$27,"SPM") -> 0 | I37: =SUMIFS($K$7:$K$27,$B$7:$B$27,F37) -> 287500000
F38: PMT | G38: =COUNTIF($B$20:$B$27,"PMT") -> 0 | I38: =SUMIFS($K$7:$K$27,$B$7:$B$27,F38) -> 60000000
F39: PRM | G39: =COUNTIF($B$20:$B$27,"PRM") -> 0 | I39: =I24 -> 100000000
F40: COMBO UTM-SPM | G40: =COUNTIF($B$20:$B$27,"COMBO UTM-SPM") -> 1 | I40: =SUMIFS($K$7:$K$27,$B$7:$B$27,F40) -> 150000000
F41: COMBO UTM-SPM-PMT | G41: =COUNTIF($B$20:$B$27,"COMBO UTM-SPM-PMT") -> 0 | I41: =SUMIFS($K$7:$K$27,$B$7:$B$27,F41) -> 0
F42: COMBO UTM-SPM-PRM-PNC | G42: =COUNTIF($B$20:$B$27,"COMBO UTM-SPM-PRM-PNC") -> 0 | I42: =SUMIFS($K$7:$K$27,$B$7:$B$27,F42) -> 0
F43: COMBO PRM-PNC | G43: =COUNTIF($B$20:$B$27,"COMBO PRM-PNC") -> 1 | I43: 0
F44: COMBO ALL DIV | G44: =COUNTIF($B$20:$B$27,"COMBO ALL DIV") -> 0 | I44: =SUMIFS($K$7:$K$27,$B$7:$B$27,F44) -> 52500000
F45: PNC | G45: =COUNTIF($B$20:$B$27,"PNC") -> 0 | I45: =J24 -> 349000000
F46: TOTAL | G46: =SUM(G36:H45) -> 5 | I46: =SUM(I36:I45) -> 1299000000
F48: LEVEL | G48: TOTAL | H48: TERISI | I48: VACANT
F49: PS | G49: =COUNTIF($G$20:$G$27,"PS") -> 4 | H49: =COUNTIF($D$20:$D$27,"PS TERISI") -> 3 | I49: =G49-H49 -> 1
F50: AE | G50: =COUNTIF($G$20:$G$27,"AE") -> 1 | H50: =COUNTIF($D$20:$D$27,"AE TERISI") -> 0 | I50: =G50-H50 -> 1
...

Sheet JABAR
F1: TARGET SALES FEBRUARI 2025
F2: BCO JAWA BARAT
B4: DIVISI RAYON | C4: DIVISI INC | D4: STATUS SF | F4: KODE RAYON (div + level + rayon) | G4: LEVEL | H4: NAMA SALES FORCE | I4: TARGET IN VALUE | J4: TARGET IN UNIT (TW) | K4: TOTAL TARGET
A6: .
A7: . | B7: UTM | C7: UTM | D7: PS TERISI | F7: UTM BDG 1 | G7: PS | H7: Rafsanjani Dimyati | I7: 85000000 | K7: =SUM(I7:J7) -> 85000000
A8: . | B8: UTM | C8: UTM | D8: PS TERISI | F8: UTM BDG 2 | G8: PS | H8: Hajar Jabaludin | I8: 95000000 | K8: =SUM(I8:J8) -> 95000000
A9: . | B9: COMBO UTM-SPM | C9: UTM | D9: PS VACANT | F9: COMBO TSK (UTM-SPM) | G9: PS | H9: Ex. Hajar Jabaludin | I9: 65000000 | K9: =SUM(I9:J9) -> 65000000
A10: . | C10: UTM | D10: DM TERISI | F10: COMBO DM JABAR 1 | G10: DM | H10: TITO AJI SANTOSO | I10: =SUM(I7:I9) -> 245000000 | J10: =SUM(J7:J9) -> 0 | K10: =SUM(I10:J10) -> 245000000
A11: .
A12: . | B12: COMBO PRM-PNC | C12: PRM | D12: AE TERISI | F12: COMBO JABAR (PRM-PNC) | G12: AE | H12: Azi Wahyudi | I12: 50000000 | J12: 349000000 | K12: =SUM(I12:J12) -> 399000000
A13: .
A14: . | C14: UTM | D14: RSM VACANT | F14: COMBO RSM JABAR 1 | G14: RSM | H14: MR. X | I14: =I10+I12 -> 295000000 | J14: =J10+J12 -> 349000000 | K14: =SUM(I14:J14) -> 644000000
A15: .
A16: . | B16: SPM | C16: SPM | D16: PS TERISI | F16: SPM BDG 1 | G16: PS | H16: Shanti Puspitasari | I16: 65000000 | K16: =SUM(I16:J16) -> 65000000
A17: . | B17: SPM | C17: SPM | D17: PS TERISI | F17: SPM BDG 2 | G17: PS | H17: Azis Permana | I17: 100000000 | K17: =SUM(I17:J17) -> 100000000
A18: . | B18: COMBO UTM-SPM | C18: SPM | D18: PS TERISI | F18: COMBO CRB (UTM-SPM) | G18: PS | H18: Putri Salsabillatuseha Syafii | I18: 70000000 | K18: =SUM(I18:J18) -> 70000000
A19: . | C19: SPM | D19: DM TERISI | F19: COMBO DM JABAR 2 | G19: DM | H19: AHMAD MASHUDI | I19: =SUM(I16:I18) -> 235000000 | J19: =SUM(J16:J18) -> 0 | K19: =SUM(I19:J19) -> 235000000
A20: .
A21: . | B21: PMT | C21: PMT | D21: PS TERISI | F21: PMT BDG 1 | G21: PS | H21: Rengganis Kusuma Dewi | I21: 20000000 | K21: =SUM(I21:J21) -> 20000000 | L21: UPDATE SF
A22: . | B22: PMT | C22: PMT | D22: PS VACANT | F22: PMT BDG 2 | G22: PS | H22: Ex. Azis Permana (vacum) | I22: 0 | K22: =SUM(I22:J22) -> 0
A23: . | C23: PMT | D23: DM VACANT | F23: PMT DM JABAR | G23: DM | H23: EX. ASEP SAEPUL MILAH S.SI | I23: =SUM(I21:I22) -> 20000000 | J23: =SUM(J21:J22) -> 0 | K23: =SUM(I23:J23) -> 20000000
A24: .
A25: . | C25: SPM | D25: RSM TERISI | F25: COMBO RSM JABAR 2 | G25: RSM | H25: DJUMAILAH KAMADJAJA | I25: =I19+I23 -> 255000000 | J25: =J19+J23 -> 0 | K25: =SUM(I25:J25) -> 255000000 | L25: UPDATE SF
A26: .
A27: . | C27: BCO | D27: BCO TERISI | F27: BCO JABAR | G27: BCO | H27: ALEK IRUN SETIARUN | I27: =I14+I19+I23 -> 550000000 | J27: =J14+J19+J23 -> 349000000 | K27: =SUM(I27:J27) -> 899000000
F37: DIVISI RAYON | G37: JUMLAH RAYON | I37: TARGET
F38: UTM | G38: =COUNTIF($B$7:$B$27,"UTM") -> 2 | I38: =SUMIFS($K$7:$K$27,$B$7:$B$27,F38) -> 180000000
F39: SPM | G39: =COUNTIF($B$7:$B$27,"SPM") -> 2 | I39: =SUMIFS($K$7:$K$27,$B$7:$B$27,F39) -> 165000000
F40: PMT | G40: =COUNTIF($B$7:$B$27,"PMT") -> 2 | I40: =SUMIFS($K$7:$K$27,$B$7:$B$27,F40) -> 20000000
F41: PRM | G41: =COUNTIF($B$7:$B$27,"PRM") -> 0 | I41: =I12 -> 50000000
F42: COMBO UTM-SPM | G42: =COUNTIF($B$7:$B$27,"COMBO UTM-SPM") -> 2 | I42: =SUMIFS($K$7:$K$27,$B$7:$B$27,F42) -> 135000000
F43: COMBO UTM-SPM-PMT | G43: =COUNTIF($B$7:$B$27,"COMBO UTM-SPM-PMT") -> 0 | I43: =SUMIFS($K$7:$K$27,$B$7:$B$27,F43) -> 0
F44: COMBO UTM-SPM-PRM-PNC | G44: =COUNTIF($B$7:$B$27,"COMBO UTM-SPM-PRM-PNC") -> 0 | I44: =SUMIFS($K$7:$K$27,$B$7:$B$27,F44) -> 0
F45: COMBO PRM-PNC | G45: =COUNTIF($B$7:$B$27,"COMBO PRM-PNC") -> 1 | I45: 0
F46: COMBO ALL DIV | G46: =COUNTIF($B$7:$B$27,"COMBO ALL DIV") -> 0 | I46: =SUMIFS($K$7:$K$27,$B$7:$B$27,F46) -> 0
F47: PNC | G47: =COUNTIF($B$7:$B$27,"PNC") -> 0 | I47: =J12 -> 349000000
F48: TOTAL | G48: =SUM(G38:H47) -> 9 | I48: =SUM(I38:I47) -> 899000000
F50: LEVEL | G50: TOTAL | H50: TERISI | I50: VACANT
F51: PS | G51: =COUNTIF($G$7:$G$27,"PS") -> 8 | H51: =COUNTIF($D$7:$D$27,"PS TERISI") -> 6 | I51: =G51-H51 -> 2
F52: AE | G52: =COUNTIF($G$7:$G$27,"AE") -> 1 | H52: =COUNTIF($D$7:$D$27,"AE TERISI") -> 1 | I52: =G52-H52 -> 0
...

Sheet JATENG
F1: TARGET SALES FEBRUARI 2025
F2: BCO JAWA TENGAH
B4: DIVISI RAYON | C4: DIVISI INC | D4: STATUS SF | F4: KODE RAYON (div + level + rayon) | G4: LEVEL | H4: NAMA SALES FORCE | I4: TARGET IN VALUE | J4: TARGET IN UNIT (TW) | K4: TOTAL TARGET
A6: .
A7: . | B7: UTM | C7: UTM | D7: PS TERISI | F7: UTM SMG 1 | G7: PS | H7: Fawzy Praditia Zunanda | I7: 70000000 | K7: =SUM(I7:J7) -> 70000000
A8: . | B8: UTM | C8: UTM | D8: PS TERISI | F8: UTM SMG 2 | G8: PS | H8: Fella Arum Septyvita | I8: 85000000 | K8: =SUM(I8:J8) -> 85000000
A9: . | B9: SPM | C9: SPM | D9: PS TERISI | F9: SPM SMG | G9: PS | H9: Fadilla Rahma Fauziah | I9: 95000000 | K9: =SUM(I9:J9) -> 95000000
A10: . | B10: COMBO UTM-SPM | C10: UTM | D10: PS TERISI | F10: COMBO TGL (UTM-SPM) | G10: PS | H10: Eko Wahyu Utomo | I10: 80000000 | K10: =SUM(I10:J10) -> 80000000
A11: . | C11: UTM | D11: DM TERISI | F11: COMBO DM SMG | G11: DM | H11: BELLA OVILIA | I11: =SUM(I7:I10) -> 330000000 | J11: =SUM(J7:J10) -> 0 | K11: =SUM(I11:J11) -> 330000000
A12: .
A13: . | B13: UTM | C13: UTM | D13: PS TERISI | F13: UTM JGJ 1 | G13: PS | H13: Aril Geovanni Saemani | I13: 125000000 | K13: =SUM(I13:J13) -> 125000000
A14: . | B14: UTM | C14: UTM | D14: PS TERISI | F14: UTM JGJ 2 | G14: PS | H14: Apriani Listi Lindia | I14: 75000000 | K14: =SUM(I14:J14) -> 75000000 | L14: UPDATE SF
A15: . | B15: SPM | C15: SPM | D15: PS VACANT | F15: SPM JGJ | G15: PS | H15: Ex. Ferdian Adi Pratama | I15: 45000000 | K15: =SUM(I15:J15) -> 45000000
A16: . | C16: UTM | D16: DM TERISI | F16: COMBO DM JGJ | G16: DM | H16: ANDREW BASKORO | I16: =SUM(I13:I15) -> 245000000 | J16: =SUM(J13:J15) -> 0 | K16: =SUM(I16:J16) -> 245000000
A17: .
A18: . | B18: UTM | C18: UTM | D18: PS TERISI | F18: UTM SOL | G18: PS | H18: Seika Reka Kurniasih | I18: 200000000 | K18: =SUM(I18:J18) -> 200000000
A19: . | B19: SPM | C19: SPM | D19: PS TERISI | F19: SPM SOL | G19: PS | H19: Fahrudin Rifa'i | I19: 75000000 | K19: =SUM(I19:J19) -> 75000000
A20: . | B20: UTM | C20: UTM | F20: UTM SOL TENDER | H20: Sales Tender Dr. Ade Putri | I20: 250000000 | K20: =SUM(I20:J20) -> 250000000
A21: . | C21: UTM | D21: DM TERISI | F21: COMBO DM SOLO | G21: DM | H21: MUHAMMAD YANU FERDIANTO | I21: =SUM(I18:I20) -> 525000000 | J21: =SUM(J18:J20) -> 0 | K21: =SUM(I21:J21) -> 525000000
A22: .
A23: . | B23: PMT | C23: PMT | D23: PS TERISI | F23: PMT SMG | G23: PS | H23: Panggah Budi Hermawan | I23: 35000000 | K23: =SUM(I23:J23) -> 35000000
A24: . | B24: PMT | C24: PMT | D24: PS TERISI | F24: PMT JOGLO | G24: PS | H24: R Drajat Heppy Radityo | I24: 40000000 | K24: =SUM(I24:J24) -> 40000000
A25: . | B25: PMT | C25: PMT | D25: PS VACANT | F25: PMT JGJ | G25: PS | H25: Ex. Yudi Dwi Hermawan (vacum) | I25: 0 | K25: =SUM(I25:J25) -> 0
A26: . | C26: PMT | D26: DM TERISI | F26: PMT DM JATENG | G26: DM | H26: VICA ALMIA | I26: =SUM(I23:I25) -> 75000000 | J26: =SUM(J23:J25) -> 0 | K26: =SUM(I26:J26) -> 75000000
A27: .
A28: . | B28: COMBO PRM-PNC | C28: PRM | D28: AM TERISI | F28: COMBO AM JATENG (PRM-PNC) | G28: AM | H28: ANANDA RIO ALIF PRADANA, S.Pd | I28: 75000000 | J28: 349000000 | K28: =SUM(I28:J28) -> 424000000
A29: .
A30: . | C30: BCO | D30: BCO TERISI | F30: BCO JATENG | G30: BCO | H30: KUSNADI SOETARDJO | I30: =I11+I16+I21+I26+I28 -> 1250000000 | J30: =J11+J16+J21+J26+J28 -> 349000000 | K30: =SUM(I30:J30) -> 1599000000
F37: DIVISI RAYON | G37: JUMLAH RAYON | I37: TARGET
F38: UTM | G38: =COUNTIF($B$7:$B$30,"UTM") -> 6 | I38: =SUMIFS($K$7:$K$30,$B$7:$B$30,F38) -> 805000000
F39: SPM | G39: =COUNTIF($B$7:$B$30,"SPM") -> 3 | I39: =SUMIFS($K$7:$K$30,$B$7:$B$30,F39) -> 215000000
F40: PMT | G40: =COUNTIF($B$7:$B$30,"PMT") -> 3 | I40: =SUMIFS($K$7:$K$30,$B$7:$B$30,F40) -> 75000000
F41: PRM | G41: =COUNTIF($B$7:$B$30,"PRM") -> 0 | I41: =I28 -> 75000000
F42: COMBO UTM-SPM | G42: =COUNTIF($B$7:$B$30,"COMBO UTM-SPM") -> 1 | I42: =SUMIFS($K$7:$K$30,$B$7:$B$30,F42) -> 80000000
F43: COMBO UTM-SPM-PMT | G43: =COUNTIF($B$7:$B$30,"COMBO UTM-SPM-PMT") -> 0 | I43: =SUMIFS($K$7:$K$30,$B$7:$B$30,F43) -> 0
F44: COMBO UTM-SPM-PRM-PNC | G44: =COUNTIF($B$7:$B$30,"COMBO UTM-SPM-PRM-PNC") -> 0 | I44: =SUMIFS($K$7:$K$30,$B$7:$B$30,F44) -> 0
F45: COMBO PRM-PNC | G45: =COUNTIF($B$7:$B$30,"COMBO PRM-PNC") -> 1 | I45: 0
F46: COMBO ALL DIV | G46: =COUNTIF($B$7:$B$30,"COMBO ALL DIV") -> 0 | I46: =SUMIFS($K$7:$K$30,$B$7:$B$30,F46) -> 0
F47: PNC | G47: =COUNTIF($B$7:$B$30,"PNC") -> 0 | I47: =J28 -> 349000000
F48: TOTAL | G48: =SUM(G38:H47) -> 14 | I48: =SUM(I38:I47) -> 1599000000
...

Sheet JATIM
F1: TARGET SALES FEBRUARI 2025
F2: BCO JAWA TIMUR
B4: DIVISI RAYON | C4: DIVISI INC | D4: STATUS SF | F4: KODE RAYON (div + level + rayon) | G4: LEVEL | H4: NAMA SALES FORCE | I4: TARGET IN VALUE | J4: TARGET IN UNIT (TW) | K4: TOTAL TARGET
A6: .
A7: . | B7: UTM | C7: UTM | D7: PS VACANT | F7: UTM SBU 1 | G7: PS | H7: Ex. Ika Rahmawati | I7: 90000000 | K7: =SUM(I7:J7) -> 90000000
A8: . | B8: UTM | C8: UTM | D8: PS TERISI | F8: UTM SBU 2 | G8: PS | H8: Fildzah Nazihah Aufarina, S.Sos | I8: 95000000 | K8: =SUM(I8:J8) -> 95000000
A9: . | B9: UTM | C9: UTM | D9: PS TERISI | F9: UTM SBS 2 | G9: PS | H9: Devinta Agnes Hapsari | I9: 100000000 | K9: =SUM(I9:J9) -> 100000000
A10: . | C10: UTM | D10: DM TERISI | F10: UTM DM JATIM 1 | G10: DM | H10: TITIE LIANTINI | I10: =SUM(I7:I9) -> 285000000 | J10: =SUM(J7:J9) -> 0 | K10: =SUM(I10:J10) -> 285000000
A11: .
A12: . | B12: UTM | C12: UTM | D12: PS TERISI | F12: UTM SBS 1 | G12: PS | H12: Assidiq Zidane Iwansyah | I12: 100000000 | K12: =SUM(I12:J12) -> 100000000
A13: . | B13: UTM | C13: UTM | D13: PS TERISI | F13: UTM MLG 1 | G13: PS | H13: Robby Prihma Septianto | I13: 80000000 | K13: =SUM(I13:J13) -> 80000000 | L13: UPDATE SF
A14: . | B14: UTM | C14: UTM | D14: PS TERISI | F14: UTM MLG 2 | G14: PS | H14: Haris Galih Wardana | I14: 130000000 | K14: =SUM(I14:J14) -> 130000000
A15: . | C15: UTM | D15: DM TERISI | F15: UTM DM JATIM 2 | G15: DM | H15: CALISA TUZZAKATTA | I15: =SUM(I12:I14) -> 310000000 | J15: =SUM(J12:J14) -> 0 | K15: =SUM(I15:J15) -> 310000000
A16: .
A17: . | B17: COMBO PRM-PNC | C17: PRM | D17: AM TERISI | F17: COMBO AM JATIM 1 (PRM-PNC) | G17: AM | H17: ASTRIA RAPRANA | I17: 65000000 | J17: 349000000 | K17: =SUM(I17:J17) -> 414000000
A18: .
A19: . | B19: COMBO PRM-PNC | C19: PRM | D19: AM TERISI | F19: COMBO AM JATIM 2 (PRM-PNC) | G19: AM | H19: ABD. MUHIS | I19: 65000000 | J19: 349000000 | K19: =SUM(I19:J19) -> 414000000
A20: .
A21: . | C21: UTM | D21: RSM TERISI | F21: COMBO RSM JATIM 1 | G21: RSM | H21: REMBULAN SEKAR EXAZIERAYANDA | I21: =I10+I15+I17+I19 -> 725000000 | J21: =J10+J15+J17+J19 -> 698000000 | K21: =SUM(I21:J21) -> 1423000000
A22: .
A23: . | B23: SPM | C23: SPM | D23: PS VACANT | F23: SPM SBY 1 | G23: PS | H23: Ex. Astria Raprana | I23: 85000000 | K23: =SUM(I23:J23) -> 85000000
A24: . | B24: SPM | C24: SPM | D24: PS TERISI | F24: SPM SBY 2 | G24: PS | H24: Citraresmi Widyarini | I24: 85000000 | K24: =SUM(I24:J24) -> 85000000
A25: . | B25: SPM | C25: SPM | D25: PS VACANT | F25: SPM MLG | G25: PS | H25: Teddy Tristyanto | I25: 45000000 | K25: =SUM(I25:J25) -> 45000000 | L25: UPDATE SF
A26: . | C26: SPM | D26: DM TERISI | F26: SPM DM JATIM | G26: DM | H26: DEDE IRAWAN | I26: =SUM(I23:I25) -> 215000000 | J26: =SUM(J23:J25) -> 0 | K26: =SUM(I26:J26) -> 215000000
A27: .
A28: . | B28: PMT | C28: PMT | D28: PS TERISI | F28: PMT SBY | G28: PS | H28: Rextio Axell Arifien | I28: 40000000 | K28: =SUM(I28:J28) -> 40000000
A29: . | B29: PMT | C29: PMT | D29: PS TERISI | F29: PMT MLG | G29: PS | H29: Ex. Teddy Tristyanto | I29: 20000000 | K29: =SUM(I29:J29) -> 20000000 | L29: MUTASI
A30: . | C30: PMT | D30: DM TERISI | F30: PMT DM JATIM | G30: DM | H30: GLORIA FEBRINA MAHARANI .I., SE | I30: =SUM(I28:I29) -> 60000000 | J30: =SUM(J28:J29) -> 0 | K30: =SUM(I30:J30) -> 60000000
A31: .
A32: . | C32: SPM | D32: RSM TERISI | F32: COMBO RSM JATIM 2 | G32: RSM | H32: SEPTIAN HADI | I32: =I26+I30 -> 275000000 | J32: =J26+J30 -> 0 | K32: =SUM(I32:J32) -> 275000000
A33: .
A34: . | C34: BCO | D34: BCO TERISI | F34: BCO JATIM | G34: BCO | H34: MARTINUS DENNY TERSIANTO | I34: =I32+I21 -> 1000000000 | J34: =J32+J21 -> 698000000 | K34: =SUM(I34:J34) -> 1698000000
F37: DIVISI RAYON | G37: JUMLAH RAYON | I37: TARGET
F38: UTM | G38: =COUNTIF($B$7:$B$34,"UTM") -> 6 | I38: =SUMIFS($K$7:$K$34,$B$7:$B$34,F38) -> 595000000
F39: SPM | G39: =COUNTIF($B$7:$B$34,"SPM") -> 3 | I39: =SUMIFS($K$7:$K$34,$B$7:$B$34,F39) -> 215000000
F40: PMT | G40: =COUNTIF($B$7:$B$34,"PMT") -> 2 | I40: =SUMIFS($K$7:$K$34,$B$7:$B$34,F40) -> 60000000
F41: PRM | G41: =COUNTIF($B$7:$B$34,"PRM") -> 0 | I41: =I17+I19 -> 130000000
F42: COMBO UTM-SPM | G42: =COUNTIF($B$7:$B$34,"COMBO UTM-SPM") -> 0 | I42: =SUMIFS($K$7:$K$34,$B$7:$B$34,F42) -> 0
F43: COMBO UTM-SPM-PMT | G43: =COUNTIF($B$7:$B$34,"COMBO UTM-SPM-PMT") -> 0 | I43: =SUMIFS($K$7:$K$34,$B$7:$B$34,F43) -> 0
F44: COMBO UTM-SPM-PRM-PNC | G44: =COUNTIF($B$7:$B$34,"COMBO UTM-SPM-PRM-PNC") -> 0 | I44: =SUMIFS($K$7:$K$34,$B$7:$B$34,F44) -> 0
...

Sheet BALINUS
F1: TARGET SALES FEBRUARI 2025
F2: SUB BCO BALI NUSRA
B4: DIVISI RAYON | C4: DIVISI INC | D4: STATUS SF | F4: KODE RAYON (div + level + rayon) | G4: LEVEL | H4: NAMA SALES FORCE | I4: TARGET IN VALUE | J4: TARGET IN UNIT (TW) | K4: TOTAL TARGET
A6: .
A7: . | B7: UTM | C7: UTM | D7: PS TERISI | F7: UTM DPS 1 | G7: PS | H7: Ni Ketut Krisna Dewi Pratidina | I7: 40000000 | K7: =SUM(I7:J7) -> 40000000
A8: . | B8: UTM | C8: UTM | D8: PS TERISI | F8: UTM DPS 2 | G8: PS | H8: Ni Putu Andiyani | I8: 90000000 | K8: =SUM(I8:J8) -> 90000000
A9: . | B9: COMBO ALL DIV | C9: UTM | D9: PS TERISI | F9: COMBO NTB (ALL DIV) | G9: PS | H9: Agus Muliadi | I9: 65000000 | K9: =SUM(I9:J9) -> 65000000
A10: . | C10: UTM | D10: DM VACANT | F10: COMBO DM BALINUS 1 | G10: DM | H10: EX. CALISA TUZZAKATTA | I10: =SUM(I7:I9) -> 195000000 | J10: =SUM(J7:J9) -> 0 | K10: =SUM(I10:J10) -> 195000000
A11: .
A12: . | B12: SPM | C12: SPM | D12: PS TERISI | F12: SPM DPS | G12: PS | H12: Putu Nila Anggraeni | I12: 60000000 | K12: =SUM(I12:J12) -> 60000000
A13: . | B13: PMT | C13: PMT | D13: PS VACANT | F13: PMT DPS | G13: PS | H13: Ex. William Rosmansyah HS | I13: 25000000 | K13: =SUM(I13:J13) -> 25000000
A14: . | B14: COMBO ALL DIV | C14: SPM | D14: PS VACANT | F14: COMBO NTT (ALL DIV) | G14: PS | H14: Mr. X | I14: 45000000 | K14: =SUM(I14:J14) -> 45000000
A15: . | C15: SPM | D15: DM VACANT | F15: COMBO DM BALINUS 2 | G15: DM | H15: MR. X | I15: =SUM(I12:I14) -> 130000000 | J15: =SUM(J12:J14) -> 0 | K15: =SUM(I15:J15) -> 130000000
A16: .
A17: . | B17: COMBO PRM-PNC | C17: PRM | D17: AM VACANT | F17: COMBO AM DPS (PRM-PNC) | G17: AM | H17: EX. HANSEN | I17: 100000000 | J17: 349000000 | K17: =SUM(I17:J17) -> 449000000 | L17: UPDATE SF
A18: .
A19: . | C19: BCO | D19: BCO TERISI | F19: SUB BCO BALI NUSRA | G19: SUB BCO | H19: HENDRY KURNIAWAN | I19: =I10+I15+I17 -> 425000000 | J19: =J10+J15+J17 -> 349000000 | K19: =SUM(I19:J19) -> 774000000
F37: DIVISI RAYON | G37: JUMLAH RAYON | I37: TARGET
F38: UTM | G38: =COUNTIF($B$7:$B$19,"UTM") -> 2 | I38: =SUMIFS($K$7:$K$19,$B$7:$B$19,F38) -> 130000000
F39: SPM | G39: =COUNTIF($B$7:$B$19,"SPM") -> 1 | I39: =SUMIFS($K$7:$K$19,$B$7:$B$19,F39) -> 60000000
F40: PMT | G40: =COUNTIF($B$7:$B$19,"PMT") -> 1 | I40: =SUMIFS($K$7:$K$19,$B$7:$B$19,F40) -> 25000000
F41: PRM | G41: =COUNTIF($B$7:$B$19,"PRM") -> 0 | I41: =I17 -> 100000000
F42: COMBO UTM-SPM | G42: =COUNTIF($B$7:$B$19,"COMBO UTM-SPM") -> 0 | I42: =SUMIFS($K$7:$K$19,$B$7:$B$19,F42) -> 0
F43: COMBO UTM-SPM-PMT | G43: =COUNTIF($B$7:$B$19,"COMBO UTM-SPM-PMT") -> 0 | I43: =SUMIFS($K$7:$K$19,$B$7:$B$19,F43) -> 0
F44: COMBO UTM-SPM-PRM-PNC | G44: =COUNTIF($B$7:$B$19,"COMBO UTM-SPM-PRM-PNC") -> 0 | I44: =SUMIFS($K$7:$K$19,$B$7:$B$19,F44) -> 0
F45: COMBO PRM-PNC | G45: =COUNTIF($B$7:$B$19,"COMBO PRM-PNC") -> 1 | I45: 0
F46: COMBO ALL DIV | G46: =COUNTIF($B$7:$B$19,"COMBO ALL DIV") -> 2 | I46: =SUMIFS($K$7:$K$19,$B$7:$B$19,F46) -> 110000000
F47: PNC | G47: =COUNTIF($B$7:$B$19,"PNC") -> 0 | I47: =J17 -> 349000000
F48: TOTAL | G48: =SUM(G38:H47) -> 7 | I48: =SUM(I38:I47) -> 774000000
F50: LEVEL | G50: TOTAL | H50: TERISI | I50: VACANT
F51: PS | G51: =COUNTIF($G$7:$G$19,"PS") -> 6 | H51: =COUNTIF($D$7:$D$19,"PS TERISI") -> 4 | I51: =G51-H51 -> 2
F52: AE | G52: =COUNTIF($G$7:$G$19,"AE") -> 0 | H52: =COUNTIF($D$7:$D$19,"AE TERISI") -> 0 | I52: =G52-H52 -> 0
F53: AM | G53: =COUNTIF($G$7:$G$19,"AM") -> 1 | H53: =COUNTIF($D$7:$D$19,"AM TERISI") -> 0 | I53: =G53-H53 -> 1
F54: DM | G54: =COUNTIF($G$7:$G$19,"DM") -> 2 | H54: =COUNTIF($D$7:$D$19,"DM TERISI") -> 0 | I54: =G54-H54 -> 2
F55: RSM | G55: =COUNTIF($G$7:$G$19,"RSM") -> 0 | H55: =COUNTIF($D$7:$D$19,"RSM TERISI") -> 0 | I55: =G55-H55 -> 0
F56: BCO | G56: 1 | H56: =COUNTIF($D$7:$D$19,"BCO TERISI") -> 1 | I56: =G56-H56 -> 0
F57: TOTAL | G57: =SUM(G51:G56) -> 10 | H57: =SUM(H51:H56) -> 5 | I57: =SUM(I51:I56) -> 5
H58: =H57/G57 -> 0.5 | I58: =I57/G57 -> 0.5

Sheet SUMBAGSEL
F1: TARGET SALES FEBRUARI 2025
F2: SUB BCO SUMBAGSEL
B4: DIVISI RAYON | C4: DIVISI INC | D4: STATUS SF | F4: KODE RAYON (div + level + rayon) | G4: LEVEL | H4: NAMA SALES FORCE | I4: TARGET IN VALUE | J4: TARGET IN UNIT (TW) | K4: TOTAL TARGET
A6: .
A7: . | B7: UTM | C7: UTM | D7: PS TERISI | F7: UTM LMP | G7: PS | H7: Wahyu Mirza Syahputra | I7: 90000000 | K7: =SUM(I7:J7) -> 90000000
A8: . | B8: SPM | C8: SPM | D8: PS TERISI | F8: SPM LMP | G8: PS | H8: Riyan Tina | I8: 70000000 | K8: =SUM(I8:J8) -> 70000000
A9: . | B9: PMT | C9: PMT | D9: PS TERISI | F9: PMT LMP | G9: PS | H9: Elfi Yanti | I9: 30000000 | K9: =SUM(I9:J9) -> 30000000
A10: . | C10: UTM | D10: DM TERISI | F10: COMBO DM LMP | G10: DM | H10: ANA MARDIA | I10: =SUM(I7:I9) -> 190000000 | J10: =SUM(J7:J9) -> 0 | K10: =SUM(I10:J10) -> 190000000
A11: .
A12: . | B12: UTM | C12: UTM | D12: PS TERISI | F12: UTM PLB 1 | G12: PS | H12: Mochtar Azni Marlani | I12: 70000000 | K12: =SUM(I12:J12) -> 70000000
A13: . | B13: UTM | C13: UTM | D13: PS TERISI | F13: UTM PLB 2 | G13: PS | H13: Yansen | I13: 75000000 | K13: =SUM(I13:J13) -> 75000000
A14: . | B14: SPM | C14: SPM | D14: PS TERISI | F14: SPM PLB | G14: PS | H14: Achmad Syukri | I14: 50000000 | K14: =SUM(I14:J14) -> 50000000
A15: . | B15: PMT | C15: PMT | D15: PS TERISI | F15: PMT PLB | G15: PS | H15: Riyadi Tri | I15: 30000000 | K15: =SUM(I15:J15) -> 30000000
A16: . | C16: UTM | D16: DM VACANT | F16: COMBO DM PLB | G16: DM | H16: EX. EVIANA ARIYANI, AMKEP | I16: =SUM(I12:I15) -> 225000000 | J16: =SUM(J12:J15) -> 0 | K16: =SUM(I16:J16) -> 225000000
A17: .
A18: . | B18: COMBO UTM-SPM-PMT | C18: UTM | D18: PS TERISI | F18: COMBO JMB (UTM-SPM-PMT) | G18: PS | H18: Ridwan | I18: 40000000 | K18: =SUM(I18:J18) -> 40000000
A19: .
A20: . | B20: COMBO ALL DIV | C20: SPM | D20: PS TERISI | F20: COMBO BKL (ALL DIV) | G20: PS | H20: Siska Mardianti | I20: 65000000 | K20: =SUM(I20:J20) -> 65000000
A21: .
A22: . | B22: COMBO PRM-PNC | C22: PRM | D22: AM VACANT | F22: COMBO AM SUMSELA (PRM-PNC) | G22: AM | H22: EX. WAHYU MIRZA SYAHPUTRA | I22: 30000000 | J22: 349000000 | K22: =SUM(I22:J22) -> 379000000
A23: .
A24: . | C24: BCO | D24: BCO TERISI | F24: SUB BCO SUMBAGSEL | G24: SUB BCO | H24: PENDI GUNAWAN THANG | I24: =I10+I16+I18+I20+I22 -> 550000000 | J24: =J10+J16+J18+J20+J22 -> 349000000 | K24: =SUM(I24:J24) -> 899000000
F37: DIVISI RAYON | G37: JUMLAH RAYON | I37: TARGET
F38: UTM | G38: =COUNTIF($B$7:$B$24,"UTM") -> 3 | I38: =SUMIFS($K$7:$K$24,$B$7:$B$24,F38) -> 235000000
F39: SPM | G39: =COUNTIF($B$7:$B$24,"SPM") -> 2 | I39: =SUMIFS($K$7:$K$24,$B$7:$B$24,F39) -> 120000000
F40: PMT | G40: =COUNTIF($B$7:$B$24,"PMT") -> 2 | I40: =SUMIFS($K$7:$K$24,$B$7:$B$24,F40) -> 60000000
F41: PRM | G41: =COUNTIF($B$7:$B$24,"PRM") -> 0 | I41: =I22 -> 30000000
F42: COMBO UTM-SPM | G42: =COUNTIF($B$7:$B$24,"COMBO UTM-SPM") -> 0 | I42: =SUMIFS($K$7:$K$24,$B$7:$B$24,F42) -> 0
F43: COMBO UTM-SPM-PMT | G43: =COUNTIF($B$7:$B$24,"COMBO UTM-SPM-PMT") -> 1 | I43: =SUMIFS($K$7:$K$24,$B$7:$B$24,F43) -> 40000000
F44: COMBO UTM-SPM-PRM-PNC | G44: =COUNTIF($B$7:$B$24,"COMBO UTM-SPM-PRM-PNC") -> 0 | I44: =SUMIFS($K$7:$K$24,$B$7:$B$24,F44) -> 0
F45: COMBO PRM-PNC | G45: =COUNTIF($B$7:$B$24,"COMBO PRM-PNC") -> 1 | I45: 0
F46: COMBO ALL DIV | G46: =COUNTIF($B$7:$B$24,"COMBO ALL DIV") -> 1 | I46: =SUMIFS($K$7:$K$24,$B$7:$B$24,F46) -> 65000000
F47: PNC | G47: =COUNTIF($B$7:$B$24,"PNC") -> 0 | I47: =J22 -> 349000000
F48: TOTAL | G48: =SUM(G38:H47) -> 10 | I48: =SUM(I38:I47) -> 899000000
F50: LEVEL | G50: TOTAL | H50: TERISI | I50: VACANT
F51: PS | G51: =COUNTIF($G$7:$G$24,"PS") -> 9 | H51: =COUNTIF($D$7:$D$24,"PS TERISI") -> 9 | I51: =G51-H51 -> 0
F52: AE | G52: =COUNTIF($G$7:$G$24,"AE") -> 0 | H52: =COUNTIF($D$7:$D$24,"AE TERISI") -> 0 | I52: =G52-H52 -> 0
F53: AM | G53: =COUNTIF($G$7:$G$24,"AM") -> 1 | H53: =COUNTIF($D$7:$D$24,"AM TERISI") -> 0 | I53: =G53-H53 -> 1
F54: DM | G54: =COUNTIF($G$7:$G$24,"DM") -> 2 | H54: =COUNTIF($D$7:$D$24,"DM TERISI") -> 1 | I54: =G54-H54 -> 1
F55: RSM | G55: =COUNTIF($G$7:$G$24,"RSM") -> 0 | H55: =COUNTIF($D$7:$D$24,"RSM TERISI") -> 0 | I55: =G55-H55 -> 0
...

Sheet SUMBARI
F1: TARGET SALES FEBRUARI 2025
F2: SUB BCO SUMBARI
B4: DIVISI RAYON | C4: DIVISI INC | D4: STATUS SF | F4: KODE RAYON (div + level + rayon) | G4: LEVEL | H4: NAMA SALES FORCE | I4: TARGET IN VALUE | J4: TARGET IN UNIT (TW) | K4: TOTAL TARGET
A6: .
A7: . | B7: COMBO UTM-SPM | C7: UTM | D7: PS TERISI | F7: COMBO PKU 1 (UTM-SPM) | G7: PS | H7: Salma Zaytunil Adha | I7: 90000000 | K7: =SUM(I7:J7) -> 90000000
A8: . | B8: COMBO UTM-SPM | C8: UTM | D8: PS TERISI | F8: COMBO PKU 2 (UTM-SPM) | G8: PS | H8: Randa Andika Pratama | I8: 80000000 | K8: =SUM(I8:J8) -> 80000000
A9: . | B9: COMBO UTM-SPM | C9: UTM | D9: PS TERISI | F9: COMBO PDG (UTM-SPM) | G9: PS | H9: Ulfa Mawarriyani | I9: 55000000 | K9: =SUM(I9:J9) -> 55000000
A10: . | B10: COMBO UTM-SPM-PMT | C10: UTM | D10: PS TERISI | F10: COMBO BKTT (UTM-SPM-PMT) | G10: PS | H10: Muldi Septira | I10: 25000000 | K10: =SUM(I10:J10) -> 25000000
A11: . | C11: UTM | D11: DM TERISI | F11: COMBO DM SUMBARI 1 | G11: DM | H11: DIANTINI SETIA UTAMI | I11: =SUM(I7:I10) -> 250000000 | J11: =SUM(J7:J10) -> 0 | K11: =SUM(I11:J11) -> 250000000
A12: .
A13: . | B13: PMT | C13: PMT | D13: PS VACANT | F13: PMT PKU | G13: PS | H13: Ex. Ricky Fernando | I13: 10000000 | K13: =SUM(I13:J13) -> 10000000
A14: . | B14: PMT | C14: PMT | D14: PS TERISI | F14: PMT PDG | G14: PS | H14: Dedi Sofendi | I14: 20000000 | K14: =SUM(I14:J14) -> 20000000
A15: . | C15: PMT | D15: DM VACANT | F15: COMBO DM SUMBARI 2 | G15: DM | H15: EX. DALAS | I15: =SUM(I13:I14) -> 30000000 | J15: =SUM(J13:J14) -> 0 | K15: =SUM(I15:J15) -> 30000000
A16: .
A17: . | B17: COMBO PRM-PNC | C17: PRM | D17: DM TERISI | F17: COMBO DM SUMBARI 3 (PRM-PNC) | G17: DM | H17: OKMAL DINI | I17: 55000000 | J17: 349000000 | K17: =SUM(I17:J17) -> 404000000
A18: .
A19: . | B19: COMBO ALL DIV | C19: UTM | D19: DM TERISI | F19: COMBO DM BTM (ALL DIV) | G19: DM | H19: ADITYA PERMADI | I19: 65000000 | K19: =SUM(I19:J19) -> 65000000
A20: .
A21: . | C21: BCO | D21: BCO TERISI | F21: SUB BCO SUMBARI | G21: SUB BCO | H21: NUR ABDUL HAQ | I21: =I11+I15+I17+I19 -> 400000000 | J21: =J11+J15+J17+J19 -> 349000000 | K21: =SUM(I21:J21) -> 749000000
F37: DIVISI RAYON | G37: JUMLAH RAYON | I37: TARGET
F38: UTM | G38: =COUNTIF($B$7:$B$21,"UTM") -> 0 | I38: =SUMIFS($K$7:$K$21,$B$7:$B$21,F38) -> 0
F39: SPM | G39: =COUNTIF($B$7:$B$21,"SPM") -> 0 | I39: =SUMIFS($K$7:$K$21,$B$7:$B$21,F39) -> 0
F40: PMT | G40: =COUNTIF($B$7:$B$21,"PMT") -> 2 | I40: =SUMIFS($K$7:$K$21,$B$7:$B$21,F40) -> 30000000
F41: PRM | G41: =COUNTIF($B$7:$B$21,"PRM") -> 0 | I41: =I17 -> 55000000
F42: COMBO UTM-SPM | G42: =COUNTIF($B$7:$B$21,"COMBO UTM-SPM") -> 3 | I42: =SUMIFS($K$7:$K$21,$B$7:$B$21,F42) -> 225000000
F43: COMBO UTM-SPM-PMT | G43: =COUNTIF($B$7:$B$21,"COMBO UTM-SPM-PMT") -> 1 | I43: =SUMIFS($K$7:$K$21,$B$7:$B$21,F43) -> 25000000
F44: COMBO UTM-SPM-PRM-PNC | G44: =COUNTIF($B$7:$B$21,"COMBO UTM-SPM-PRM-PNC") -> 0 | I44: =SUMIFS($K$7:$K$21,$B$7:$B$21,F44) -> 0
F45: COMBO PRM-PNC | G45: =COUNTIF($B$7:$B$21,"COMBO PRM-PNC") -> 1 | I45: 0
F46: COMBO ALL DIV | G46: =COUNTIF($B$7:$B$21,"COMBO ALL DIV") -> 1 | I46: =SUMIFS($K$7:$K$21,$B$7:$B$21,F46) -> 65000000
F47: PNC | G47: =COUNTIF($B$7:$B$21,"PNC") -> 0 | I47: =J17 -> 349000000
F48: TOTAL | G48: =SUM(G38:H47) -> 8 | I48: =SUM(I38:I47) -> 749000000
F50: LEVEL | G50: TOTAL | H50: TERISI | I50: VACANT
F51: PS | G51: =COUNTIF($G$7:$G$21,"PS") -> 6 | H51: =COUNTIF($D$7:$D$21,"PS TERISI") -> 5 | I51: =G51-H51 -> 1
F52: AE | G52: =COUNTIF($G$7:$G$21,"AE") -> 0 | H52: =COUNTIF($D$7:$D$21,"AE TERISI") -> 0 | I52: =G52-H52 -> 0
F53: AM | G53: =COUNTIF($G$7:$G$21,"AM") -> 0 | H53: =COUNTIF($D$7:$D$21,"AM TERISI") -> 0 | I53: =G53-H53 -> 0
F54: DM | G54: =COUNTIF($G$7:$G$21,"DM") -> 4 | H54: =COUNTIF($D$7:$D$21,"DM TERISI") -> 3 | I54: =G54-H54 -> 1
F55: RSM | G55: =COUNTIF($G$7:$G$21,"RSM") -> 0 | H55: =COUNTIF($D$7:$D$21,"RSM TERISI") -> 0 | I55: =G55-H55 -> 0
F56: BCO | G56: 1 | H56: =COUNTIF($D$7:$D$21,"BCO TERISI") -> 1 | I56: =G56-H56 -> 0
F57: TOTAL | G57: =SUM(G51:G56) -> 11 | H57: =SUM(H51:H56) -> 9 | I57: =SUM(I51:I56) -> 2
H58: =H57/G57 -> 0.81818182 | I58: =I57/G57 -> 0.18181818

Sheet SUMUT ACEH
F1: TARGET SALES FEBRUARI 2025
F2: BCO SUMUT ACEH
B4: DIVISI RAYON | C4: DIVISI INC | D4: STATUS SF | F4: KODE RAYON (div + level + rayon) | G4: LEVEL | H4: NAMA SALES FORCE | I4: TARGET IN VALUE | J4: TARGET IN UNIT (TW) | K4: TOTAL TARGET
A6: .
A7: . | B7: UTM | C7: UTM | D7: PS TERISI | F7: UTM MDN 1 | G7: PS | H7: Fadilah Ramadani Harahap | I7: 105000000 | K7: =SUM(I7:J7) -> 105000000
A8: . | B8: UTM | C8: UTM | D8: PS TERISI | F8: UTM MDN 2 | G8: PS | H8: Gilang Azhari | I8: 130000000 | K8: =SUM(I8:J8) -> 130000000
A9: . | B9: UTM | C9: UTM | D9: PS TERISI | F9: UTM MDN 3 | G9: PS | H9: M Khairul Fahmi Sadly | I9: 80000000 | K9: =SUM(I9:J9) -> 80000000
A10: . | B10: UTM | C10: UTM | D10: PS TERISI | F10: UTM MDN 4 | G10: PS | H10: Shela Sasta Fiana | I10: 110000000 | K10: =SUM(I10:J10) -> 110000000
A11: . | C11: UTM | D11: DM TERISI | F11: UTM DM SUMUT | G11: DM | H11: BUNGA FITRIANI | I11: =SUM(I7:I10) -> 425000000 | J11: =SUM(J7:J10) -> 0 | K11: =SUM(I11:J11) -> 425000000
A12: .
A13: . | B13: SPM | C13: SPM | D13: PS VACANT | F13: SPM MDN 1 | G13: PS | H13: Ex. Tia Lestari | I13: 60000000 | K13: =SUM(I13:J13) -> 60000000
A14: . | B14: SPM | C14: SPM | D14: PS TERISI | F14: SPM MDN 2 | G14: PS | H14: Muhammad Sandi | I14: 60000000 | K14: =SUM(I14:J14) -> 60000000
A15: . | C15: SPM | D15: DM VACANT | F15: SPM DM SUMUT | G15: DM | H15: EX. BUNGA FITRIANI | I15: =SUM(I13:I14) -> 120000000 | J15: =SUM(J13:J14) -> 0 | K15: =SUM(I15:J15) -> 120000000
A16: .
A17: . | B17: COMBO PRM-PNC | C17: PRM | D17: AM VACANT | F17: COMBO AM SUMUT ACEH (PRM-PNC) | G17: AM | H17: EX. WAHYU AGUSTINUS SITORUS | I17: 50000000 | J17: 349000000 | K17: =SUM(I17:J17) -> 399000000
A18: .
A19: . | C19: UTM | D19: RSM VACANT | F19: COMBO RSM SUMUT ACEH | G19: RSM | H19: MR. X | I19: =I11+I15+I17 -> 595000000 | J19: =J11+J15+J17 -> 349000000 | K19: =SUM(I19:J19) -> 944000000
A20: .
A21: . | B21: PMT | C21: PMT | D21: PS TERISI | F21: PMT MDN | G21: PS | H21: Supandi Maulana | I21: 65000000 | K21: =SUM(I21:J21) -> 65000000
A22: . | B22: PMT | C22: PMT | D22: PS VACANT | F22: PMT ACH | G22: PS | H22: Ex. Khairuddin | I22: 25000000 | K22: =SUM(I22:J22) -> 25000000
A23: . | C23: PMT | D23: DM TERISI | F23: PMT DM SUMUT | G23: DM | H23: DICKY ARIE TARIGAN, SKM | I23: =SUM(I21:I22) -> 90000000 | J23: =SUM(J21:J22) -> 0 | K23: =SUM(I23:J23) -> 90000000
A24: .
A25: . | B25: COMBO UTM-SPM | C25: UTM | D25: PS TERISI | F25: COMBO ACH 1 (UTM-SPM) | G25: PS | H25: Jumadil Rani | I25: 120000000 | K25: =SUM(I25:J25) -> 120000000
A26: . | B26: COMBO UTM-SPM | C26: UTM | D26: PS TERISI | F26: COMBO ACH 2 (UTM-SPM) | G26: PS | H26: Muhammad Irsyadi Qathnizar | I26: 95000000 | K26: =SUM(I26:J26) -> 95000000
A27: . | C27: UTM | D27: DM TERISI | F27: COMBO DM ACEH | G27: DM | H27: ISMAIL. AMD | I27: =SUM(I25:I26) -> 215000000 | J27: =SUM(J25:J26) -> 0 | K27: =SUM(I27:J27) -> 215000000
A28: .
A29: . | C29: BCO | D29: BCO TERISI | F29: BCO SUMUT ACEH | G29: BCO | H29: KURNIAWAN | I29: =I19+I23+I27 -> 900000000 | J29: =J19+J23+J27 -> 349000000 | K29: =SUM(I29:J29) -> 1249000000
F37: DIVISI RAYON | G37: JUMLAH RAYON | I37: TARGET
F38: UTM | G38: =COUNTIF($B$7:$B$29,"UTM") -> 4 | I38: =SUMIFS($K$7:$K$29,$B$7:$B$29,F38) -> 425000000
F39: SPM | G39: =COUNTIF($B$7:$B$29,"SPM") -> 2 | I39: =SUMIFS($K$7:$K$29,$B$7:$B$29,F39) -> 120000000
F40: PMT | G40: =COUNTIF($B$7:$B$29,"PMT") -> 2 | I40: =SUMIFS($K$7:$K$29,$B$7:$B$29,F40) -> 90000000
F41: PRM | G41: =COUNTIF($B$7:$B$29,"PRM") -> 0 | I41: =I17 -> 50000000
F42: COMBO UTM-SPM | G42: =COUNTIF($B$7:$B$29,"COMBO UTM-SPM") -> 2 | I42: =SUMIFS($K$7:$K$29,$B$7:$B$29,F42) -> 215000000
F43: COMBO UTM-SPM-PMT | G43: =COUNTIF($B$7:$B$29,"COMBO UTM-SPM-PMT") -> 0 | I43: =SUMIFS($K$7:$K$29,$B$7:$B$29,F43) -> 0
F44: COMBO UTM-SPM-PRM-PNC | G44: =COUNTIF($B$7:$B$29,"COMBO UTM-SPM-PRM-PNC") -> 0 | I44: =SUMIFS($K$7:$K$29,$B$7:$B$29,F44) -> 0
F45: COMBO PRM-PNC | G45: =COUNTIF($B$7:$B$29,"COMBO PRM-PNC") -> 1 | I45: 0
F46: COMBO ALL DIV | G46: =COUNTIF($B$7:$B$29,"COMBO ALL DIV") -> 0 | I46: =SUMIFS($K$7:$K$29,$B$7:$B$29,F46) -> 0
F47: PNC | G47: =COUNTIF($B$7:$B$29,"PNC") -> 0 | I47: =J17 -> 349000000
F48: TOTAL | G48: =SUM(G38:H47) -> 11 | I48: =SUM(I38:I47) -> 1249000000
F50: LEVEL | G50: TOTAL | H50: TERISI | I50: VACANT
...

Sheet SULAWESI
F1: TARGET SALES FEBRUARI 2025
F2: BCO SULAWESI
B4: DIVISI RAYON | C4: DIVISI INC | D4: STATUS SF | F4: KODE RAYON (div + level + rayon) | G4: LEVEL | H4: NAMA SALES FORCE | I4: TARGET IN VALUE | J4: TARGET IN UNIT (TW) | K4: TOTAL TARGET
A6: .
A7: . | B7: UTM | C7: UTM | D7: PS TERISI | F7: UTM MKS 1 | G7: PS | H7: Yuliati, SE | I7: 75000000 | K7: =SUM(I7:J7) -> 75000000
A8: . | B8: UTM | C8: UTM | D8: PS TERISI | F8: UTM MKS 2 | G8: PS | H8: Farhan Fahrezzy | I8: 70000000 | K8: =SUM(I8:J8) -> 70000000
A9: . | B9: COMBO ALL DIV | C9: UTM | D9: PS TERISI | F9: COMBO KDI (ALL DIV) | G9: PS | H9: Rusdi T | I9: 70000000 | K9: =SUM(I9:J9) -> 70000000
A10: . | C10: UTM | D10: DM TERISI | F10: COMBO DM SULAWESI 1 | G10: DM | H10: HARDY | I10: =SUM(I7:I9) -> 215000000 | J10: =SUM(J7:J9) -> 0 | K10: =SUM(I10:J10) -> 215000000
A11: .
A12: . | B12: SPM | C12: SPM | D12: PS TERISI | F12: SPM MKS | G12: PS | H12: Indra Salim | I12: 70000000 | K12: =SUM(I12:J12) -> 70000000
A13: . | B13: PMT | C13: PMT | D13: PS TERISI | F13: PMT MKS | G13: PS | H13: Abd Rahman HM | I13: 30000000 | K13: =SUM(I13:J13) -> 30000000
A14: . | B14: COMBO ALL DIV | C14: UTM | D14: PS VACANT | F14: COMBO AMBON (ALL DIV) | G14: PS | H14: Mr. X | I14: 35000000 | K14: =SUM(I14:J14) -> 35000000
A15: . | C15: UTM | D15: DM VACANT | F15: COMBO DM SULAWESI 2 | G15: DM | H15: EX. MUH HASBI HASAIRIN, SE | I15: =SUM(I12:I14) -> 135000000 | J15: =SUM(J12:J14) -> 0 | K15: =SUM(I15:J15) -> 135000000
A16: .
A17: . | B17: COMBO ALL DIV | C17: UTM | D17: DM VACANT | F17: COMBO DM MATEGO (ALL DIV) | G17: DM | H17: MR. X | I17: 50000000 | K17: =SUM(I17:J17) -> 50000000
A18: .
A19: . | B19: COMBO PRM-PNC | C19: PRM | D19: AM VACANT | F19: COMBO AM MKS (PRM-PNC) | G19: AM | H19: MR. X | I19: 50000000 | J19: 349000000 | K19: =SUM(I19:J19) -> 399000000
A20: .
A21: . | C21: BCO | D21: BCO TERISI | F21: BCO SULAWESI | G21: BCO | H21: GERALDUS YOMAREKA PUTRAKA | I21: =I10+I15+I17+I19 -> 450000000 | J21: =J10+J15+J17+J19 -> 349000000 | K21: =SUM(I21:J21) -> 799000000
F23: DIVISI RAYON | G23: JUMLAH RAYON | I23: TARGET
F24: UTM | G24: =COUNTIF($B$7:$B$21,"UTM") -> 2 | I24: =SUMIFS($K$7:$K$21,$B$7:$B$21,F24) -> 145000000
F25: SPM | G25: =COUNTIF($B$7:$B$21,"SPM") -> 1 | I25: =SUMIFS($K$7:$K$21,$B$7:$B$21,F25) -> 70000000
F26: PMT | G26: =COUNTIF($B$7:$B$21,"PMT") -> 1 | I26: =SUMIFS($K$7:$K$21,$B$7:$B$21,F26) -> 30000000
F27: PRM | G27: =COUNTIF($B$7:$B$21,"PRM") -> 0 | I27: =I19 -> 50000000
F28: COMBO UTM-SPM | G28: =COUNTIF($B$7:$B$21,"COMBO UTM-SPM") -> 0 | I28: =SUMIFS($K$7:$K$21,$B$7:$B$21,F28) -> 0
F29: COMBO UTM-SPM-PMT | G29: =COUNTIF($B$7:$B$21,"COMBO UTM-SPM-PMT") -> 0 | I29: =SUMIFS($K$7:$K$21,$B$7:$B$21,F29) -> 0
F30: COMBO UTM-SPM-PRM-PNC | G30: =COUNTIF($B$7:$B$21,"COMBO UTM-SPM-PRM-PNC") -> 0 | I30: =SUMIFS($K$7:$K$21,$B$7:$B$21,F30) -> 0
F31: COMBO PRM-PNC | G31: =COUNTIF($B$7:$B$21,"COMBO PRM-PNC") -> 1 | I31: 0
F32: COMBO ALL DIV | G32: =COUNTIF($B$7:$B$21,"COMBO ALL DIV") -> 3 | I32: =SUMIFS($K$7:$K$21,$B$7:$B$21,F32) -> 155000000
F33: PNC | G33: =COUNTIF($B$7:$B$21,"PNC") -> 0 | I33: =J19 -> 349000000
F34: TOTAL | G34: =SUM(G24:H33) -> 8 | I34: =SUM(I24:I33) -> 799000000
F36: LEVEL | G36: TOTAL | H36: TERISI | I36: VACANT
F37: PS | G37: =COUNTIF($G$7:$G$21,"PS") -> 6 | H37: =COUNTIF($D$7:$D$21,"PS TERISI") -> 5 | I37: =G37-H37 -> 1
F38: AE | G38: =COUNTIF($G$7:$G$21,"AE") -> 0 | H38: =COUNTIF($D$7:$D$21,"AE TERISI") -> 0 | I38: =G38-H38 -> 0
F39: AM | G39: =COUNTIF($G$7:$G$21,"AM") -> 1 | H39: =COUNTIF($D$7:$D$21,"AM TERISI") -> 0 | I39: =G39-H39 -> 1
F40: DM | G40: =COUNTIF($G$7:$G$21,"DM") -> 3 | H40: =COUNTIF($D$7:$D$21,"DM TERISI") -> 1 | I40: =G40-H40 -> 2
F41: RSM | G41: =COUNTIF($G$7:$G$21,"RSM") -> 0 | H41: =COUNTIF($D$7:$D$21,"RSM TERISI") -> 0 | I41: =G41-H41 -> 0
F42: BCO | G42: =COUNTIF($G$7:$G$21,"BCO") -> 1 | H42: =COUNTIF($D$7:$D$21,"BCO TERISI") -> 1 | I42: =G42-H42 -> 0
F43: TOTAL | G43: =SUM(G37:G42) -> 11 | H43: =SUM(H37:H42) -> 7 | I43: =SUM(I37:I42) -> 4
H44: =H43/G43 -> 0.63636364 | I44: =I43/G43 -> 0.36363636

Sheet KALIMANTAN
F1: TARGET SALES FEBRUARI 2025
F2: BCO KALIMANTAN
B4: DIVISI RAYON | C4: DIVISI INC | D4: STATUS SF | F4: KODE RAYON (div + level + rayon) | G4: LEVEL | H4: NAMA SALES FORCE | I4: TARGET IN VALUE | J4: TARGET IN UNIT (TW) | K4: TOTAL TARGET
A6: .
A7: . | B7: COMBO UTM-SPM | C7: UTM | D7: PS TERISI | F7: COMBO BJM (UTM-SPM) | G7: PS | H7: Raudatul Madina | I7: 90000000 | K7: =SUM(I7:J7) -> 90000000 | L7: UPDATE SF
A8: . | B8: COMBO PRM-PNC | C8: PRM | D8: AE VACANT | F8: COMBO KALSEL (PRM-PNC) | G8: AE | H8: Ex. Gina Anggraini | I8: 40000000 | J8: 349000000 | K8: =SUM(I8:J8) -> 389000000
A9: . | C9: UTM | D9: DM TERISI | F9: COMBO DM KALSEL | G9: DM | H9: NANA FITRIYAH | I9: =SUM(I7:I8) -> 130000000 | J9: =SUM(J7:J8) -> 349000000 | K9: =SUM(I9:J9) -> 479000000
A10: .
A11: . | B11: COMBO UTM-SPM | C11: UTM | D11: PS TERISI | F11: COMBO SMD (UTM-SPM) | G11: PS | H11: Dedy Putra Pasaribu | I11: 70000000 | K11: =SUM(I11:J11) -> 70000000
A12: . | B12: COMBO UTM-SPM | C12: UTM | D12: PS TERISI | F12: COMBO BPP (UTM-SPM) | G12: PS | H12: Dian Puji Susanti Aswalestari | I12: 25000000 | K12: =SUM(I12:J12) -> 25000000
A13: . | B13: COMBO PRM-PNC | C13: PRM | D13: AE VACANT | F13: COMBO KALTIM (PRM-PNC) | G13: AE | H13: Mr. X | I13: 25000000 | J13: 349000000 | K13: =SUM(I13:J13) -> 374000000
A14: . | C14: UTM | D14: DM VACANT | F14: COMBO DM KALTIM | G14: DM | H14: MR. X | I14: =SUM(I11:I13) -> 120000000 | J14: =SUM(J11:J13) -> 349000000 | K14: =SUM(I14:J14) -> 469000000
A15: .
A16: . | B16: PMT | C16: PMT | D16: PS TERISI | F16: PMT BJM | G16: PS | H16: Sri Ratna Novia | I16: 55000000 | K16: =SUM(I16:J16) -> 55000000
A17: . | B17: PMT | C17: PMT | D17: PS VACANT | F17: PMT KALTIM | G17: PS | H17: Ex. Mukhammad Faisal Ardiyansah | I17: 20000000 | K17: =SUM(I17:J17) -> 20000000
A18: . | C18: PMT | D18: DM TERISI | F18: PMT DM KALSELTIM | G18: DM | H18: GT RIDHO PRASETYA | I18: =SUM(I16:I17) -> 75000000 | J18: =SUM(J16:J17) -> 0 | K18: =SUM(I18:J18) -> 75000000
A19: .
A20: . | C20: BCO | D20: BCO TERISI | F20: SUB BCO KALIMANTAN | G20: SUB BCO | H20: RINI RUSTIYAWATI | I20: =I9+I14+I18 -> 325000000 | J20: =J9+J14+J18 -> 698000000 | K20: =SUM(I20:J20) -> 1023000000
F37: DIVISI RAYON | G37: JUMLAH RAYON | I37: TARGET
F38: UTM | G38: =COUNTIF($B$7:$B$20,"UTM") -> 0 | I38: =SUMIFS($K$7:$K$20,$B$7:$B$20,F38) -> 0
F39: SPM | G39: =COUNTIF($B$7:$B$20,"SPM") -> 0 | I39: =SUMIFS($K$7:$K$20,$B$7:$B$20,F39) -> 0
F40: PMT | G40: =COUNTIF($B$7:$B$20,"PMT") -> 2 | I40: =SUMIFS($K$7:$K$20,$B$7:$B$20,F40) -> 75000000
F41: PRM | G41: =COUNTIF($B$7:$B$20,"PRM") -> 0 | I41: =I8+I13 -> 65000000
F42: COMBO UTM-SPM | G42: =COUNTIF($B$7:$B$20,"COMBO UTM-SPM") -> 3 | I42: =SUMIFS($K$7:$K$20,$B$7:$B$20,F42) -> 185000000
F43: COMBO UTM-SPM-PMT | G43: =COUNTIF($B$7:$B$20,"COMBO UTM-SPM-PMT") -> 0 | I43: =SUMIFS($K$7:$K$20,$B$7:$B$20,F43) -> 0
F44: COMBO UTM-SPM-PRM-PNC | G44: =COUNTIF($B$7:$B$20,"COMBO UTM-SPM-PRM-PNC") -> 0 | I44: =SUMIFS($K$7:$K$20,$B$7:$B$20,F44) -> 0
F45: COMBO PRM-PNC | G45: =COUNTIF($B$7:$B$20,"COMBO PRM-PNC") -> 2 | I45: 0
F46: COMBO ALL DIV | G46: =COUNTIF($B$7:$B$20,"COMBO ALL DIV") -> 0 | I46: =SUMIFS($K$7:$K$20,$B$7:$B$20,F46) -> 0
F47: PNC | G47: =COUNTIF($B$7:$B$20,"PNC") -> 0 | I47: =J8+J13 -> 698000000
F48: TOTAL | G48: =SUM(G38:H47) -> 7 | I48: =SUM(I38:I47) -> 1023000000
F50: LEVEL | G50: TOTAL | H50: TERISI | I50: VACANT
F51: PS | G51: =COUNTIF($G$7:$G$20,"PS") -> 5 | H51: =COUNTIF($D$7:$D$20,"PS TERISI") -> 4 | I51: =G51-H51 -> 1
F52: AE | G52: =COUNTIF($G$7:$G$20,"AE") -> 2 | H52: =COUNTIF($D$7:$D$20,"AE TERISI") -> 0 | I52: =G52-H52 -> 2
F53: AM | G53: =COUNTIF($G$7:$G$20,"AM") -> 0 | H53: =COUNTIF($D$7:$D$20,"AM TERISI") -> 0 | I53: =G53-H53 -> 0
F54: DM | G54: =COUNTIF($G$7:$G$20,"DM") -> 3 | H54: =COUNTIF($D$7:$D$20,"DM TERISI") -> 2 | I54: =G54-H54 -> 1
F55: RSM | G55: =COUNTIF($G$7:$G$20,"RSM") -> 0 | H55: =COUNTIF($D$7:$D$20,"RSM TERISI") -> 0 | I55: =G55-H55 -> 0
F56: BCO | G56: 1 | H56: =COUNTIF($D$7:$D$20,"BCO TERISI") -> 1 | I56: =G56-H56 -> 0
F57: TOTAL | G57: =SUM(G51:G56) -> 11 | H57: =SUM(H51:H56) -> 7 | I57: =SUM(I51:I56) -> 4
H58: =H57/G57 -> 0.63636364 | I58: =I57/G57 -> 0.36363636

Sheet SUM
B1: RANGKUMAN TARGET SALES NASIONAL - FEBRUARI 2025
B3: WILAYAH | C3: HEAD SALES | D3: UTM | E3: SPM | F3: PMT | G3: PRM | H3: COMBO UTM-SPM | I3: COMBO UTM-SPM- PMT | J3: COMBO ALL DIV | K3: TOTAL TARGET (TANPA PNC) | N3: PNC | O3: TOTAL TARGET (DENGAN PNC)
K5: TARGET | L5: % | O5: TARGET | P5: %
B6: ='DKI 1'!F29 -> BCO DKI 1 | C6: ='DKI 1'!H29 -> RIALDI AGUSTIAN | D6: ='DKI 1'!$I$38 -> 595000000 | E6: ='DKI 1'!$I$39 -> 370000000 | F6: ='DKI 1'!$I$40 -> 110000000 | G6: ='DKI 1'!$I$41 -> 60000000 | H6: ='DKI 1'!$I$42 -> 0 | I6: ='DKI 1'!$I$43 -> 65000000 | J6: ='DKI 1'!$I$46 -> 0 | K6: =SUM(D6:J6) -> 1200000000 | L6: =K6/$K$17 -> 0.15 | N6: ='DKI 1'!J29/3 -> 1.1633333e+08 | O6: =K6+N6 -> 1.3163333e+09 | P6: =O6/$O$17 -> 0.13838175 | R6: UTM | S6: 4700000000
B7: ='DKI 2'!F27 -> BCO DKI 2 | C7: ='DKI 2'!H27 -> M. IQBAL GAFFAR | D7: ='DKI 2'!$I$36 -> 300000000 | E7: ='DKI 2'!$I$37 -> 287500000 | F7: ='DKI 2'!$I$38 -> 60000000 | G7: ='DKI 2'!$I$39 -> 100000000 | H7: ='DKI 2'!$I$40 -> 150000000 | I7: ='DKI 2'!$I$41 -> 0 | J7: ='DKI 2'!$I$44 -> 52500000 | K7: =SUM(D7:J7) -> 950000000 | L7: =K7/$K$17 -> 0.11875 | N7: ='DKI 2'!J27/3 -> 1.1633333e+08 | O7: =K7+N7 -> 1.0663333e+09 | P7: =O7/$O$17 -> 0.11210008 | R7: SPM | S7: 1800000000
B8: =JABAR!F27 -> BCO JABAR | C8: =JABAR!H27 -> ALEK IRUN SETIARUN | D8: =JABAR!$I$38 -> 180000000 | E8: =JABAR!$I$39 -> 165000000 | F8: =JABAR!$I$40 -> 20000000 | G8: =JABAR!$I$41 -> 50000000 | H8: =JABAR!$I$42 -> 135000000 | I8: =JABAR!$I$43 -> 0 | J8: =JABAR!$I$46 -> 0 | K8: =SUM(D8:J8) -> 550000000 | L8: =K8/$K$17 -> 0.06875 | N8: =JABAR!J27/3 -> 1.1633333e+08 | O8: =K8+N8 -> 6.6633333e+08 | P8: =O8/$O$17 -> 0.07004941 | R8: PMT | S8: 500000000
B9: =JATENG!F30 -> BCO JATENG | C9: =JATENG!H30 -> KUSNADI SOETARDJO | D9: =JATENG!$I$38 -> 805000000 | E9: =JATENG!$I$39 -> 215000000 | F9: =JATENG!$I$40 -> 75000000 | G9: =JATENG!$I$41 -> 75000000 | H9: =JATENG!$I$42 -> 80000000 | I9: =JATENG!$I$43 -> 0 | J9: =JATENG!$I$46 -> 0 | K9: =SUM(D9:J9) -> 1250000000 | L9: =K9/$K$17 -> 0.15625 | N9: =JATENG!J30/3 -> 1.1633333e+08 | O9: =K9+N9 -> 1.3663333e+09 | P9: =O9/$O$17 -> 0.14363808 | R9: PRM | S9: 500000000
B10: =JATIM!F34 -> BCO JATIM | C10: =JATIM!H34 -> MARTINUS DENNY TERSIANTO | D10: =JATIM!$I$38 -> 595000000 | E10: =JATIM!$I$39 -> 215000000 | F10: =JATIM!$I$40 -> 60000000 | G10: =JATIM!$I$41 -> 130000000 | H10: =JATIM!$I$42 -> 0 | I10: =JATIM!$I$43 -> 0 | J10: =JATIM!$I$46 -> 0 | K10: =SUM(D10:J10) -> 1000000000 | L10: =K10/$K$17 -> 0.125 | N10: =JATIM!J34/3 -> 2.3266667e+08 | O10: =K10+N10 -> 1.2326667e+09 | P10: =O10/$O$17 -> 0.12958615 | S10: =SUM(S6:S9) -> 7500000000
B11: =BALINUS!F19 -> SUB BCO BALI NUSRA | C11: =BALINUS!H19 -> HENDRY KURNIAWAN | D11: =BALINUS!$I$38 -> 130000000 | E11: =BALINUS!$I$39 -> 60000000 | F11: =BALINUS!$I$40 -> 25000000 | G11: =BALINUS!$I$41 -> 100000000 | H11: =BALINUS!$I$42 -> 0 | I11: =BALINUS!$I$43 -> 0 | J11: =BALINUS!$I$46 -> 110000000 | K11: =SUM(D11:J11) -> 425000000 | L11: =K11/$K$17 -> 0.053125 | N11: =BALINUS!J19/3 -> 1.1633333e+08 | O11: =K11+N11 -> 5.4133333e+08 | P11: =O11/$O$17 -> 0.056908575
B12: =SUMBAGSEL!F24 -> SUB BCO SUMBAGSEL | C12: =SUMBAGSEL!H24 -> PENDI GUNAWAN THANG | D12: =SUMBAGSEL!$I$38 -> 235000000 | E12: =SUMBAGSEL!$I$39 -> 120000000 | F12: =SUMBAGSEL!$I$40 -> 60000000 | G12: =SUMBAGSEL!$I$41 -> 30000000 | H12: =SUMBAGSEL!$I$42 -> 0 | I12: =SUMBAGSEL!$I$43 -> 40000000 | J12: =SUMBAGSEL!$I$46 -> 65000000 | K12: =SUM(D12:J12) -> 550000000 | L12: =K12/$K$17 -> 0.06875 | N12: =SUMBAGSEL!J24/3 -> 1.1633333e+08 | O12: =K12+N12 -> 6.6633333e+08 | P12: =O12/$O$17 -> 0.07004941 | R12: PNC | S12: 1200000000
B13: =SUMBARI!F21 -> SUB BCO SUMBARI | C13: =SUMBARI!H21 -> NUR ABDUL HAQ | D13: =SUMBARI!$I$38 -> 0 | E13: =SUMBARI!$I$39 -> 0 | F13: =SUMBARI!$I$40 -> 30000000 | G13: =SUMBARI!$I$41 -> 55000000 | H13: =SUMBARI!$I$42 -> 225000000 | I13: =SUMBARI!$I$43 -> 25000000 | J13: =SUMBARI!$I$46 -> 65000000 | K13: =SUM(D13:J13) -> 400000000 | L13: =K13/$K$17 -> 0.05 | N13: =SUMBARI!J21/3 -> 1.1633333e+08 | O13: =K13+N13 -> 5.1633333e+08 | P13: =O13/$O$17 -> 0.054280408 | S13: =S10+S12 -> 8700000000
B14: ='SUMUT ACEH'!F29 -> BCO SUMUT ACEH | C14: ='SUMUT ACEH'!H29 -> KURNIAWAN | D14: ='SUMUT ACEH'!$I$38 -> 425000000 | E14: ='SUMUT ACEH'!$I$39 -> 120000000 | F14: ='SUMUT ACEH'!$I$40 -> 90000000 | G14: ='SUMUT ACEH'!$I$41 -> 50000000 | H14: ='SUMUT ACEH'!$I$42 -> 215000000 | I14: ='SUMUT ACEH'!$I$43 -> 0 | J14: ='SUMUT ACEH'!$I$46 -> 0 | K14: =SUM(D14:J14) -> 900000000 | L14: =K14/$K$17 -> 0.1125 | N14: ='SUMUT ACEH'!J29/3 -> 1.1633333e+08 | O14: =K14+N14 -> 1.0163333e+09 | P14: =O14/$O$17 -> 0.10684375
B15: =SULAWESI!F21 -> BCO SULAWESI | C15: =SULAWESI!H21 -> GERALDUS YOMAREKA PUTRAKA | D15: =SULAWESI!$I$24 -> 145000000 | E15: =SULAWESI!$I$25 -> 70000000 | F15: =SULAWESI!$I$26 -> 30000000 | G15: =SULAWESI!$I$27 -> 50000000 | H15: =SULAWESI!$I$28 -> 0 | I15: =SULAWESI!$I$29 -> 0 | J15: =SULAWESI!$I$32 -> 155000000 | K15: =SUM(D15:J15) -> 450000000 | L15: =K15/$K$17 -> 0.05625 | N15: =SULAWESI!J21/3 -> 1.1633333e+08 | O15: =K15+N15 -> 5.6633333e+08 | P15: =O15/$O$17 -> 0.059536742
B16: =KALIMANTAN!F20 -> SUB BCO KALIMANTAN | C16: =KALIMANTAN!H20 -> RINI RUSTIYAWATI | D16: =KALIMANTAN!$I$38 -> 0 | E16: =KALIMANTAN!$I$39 -> 0 | F16: =KALIMANTAN!$I$40 -> 75000000 | G16: =KALIMANTAN!$I$41 -> 65000000 | H16: =KALIMANTAN!$I$42 -> 185000000 | I16: =KALIMANTAN!$I$43 -> 0 | J16: =KALIMANTAN!$I$46 -> 0 | K16: =SUM(D16:J16) -> 325000000 | L16: =K16/$K$17 -> 0.040625 | N16: =KALIMANTAN!J20/3 -> 2.3266667e+08 | O16: =K16+N16 -> 5.5766667e+08 | P16: =O16/$O$17 -> 0.058625644 | S16: =S13-O17 -> -8.1233333e+08
B17: TOTAL TARGET GENERAL SALES MARKETING MANAGER (GSMM) | C17: ISMARIA HANDRIANI | D17: =SUM(D6:D16) -> 3410000000 | E17: =SUM(E6:E16) -> 1622500000 | F17: =SUM(F6:F16) -> 635000000 | G17: =SUM(G6:G16) -> 765000000 | H17: =SUM(H6:H16) -> 990000000 | I17: =SUM(I6:I16) -> 130000000 | J17: =SUM(J6:J16) -> 447500000 | K17: =SUM(K6:K16) -> 8000000000 | L17: =K17/$K$17 -> 1 | N17: =SUM(N6:N16) -> 1.5123333e+09 | O17: =SUM(O6:O16) -> 9.5123333e+09 | P17: =O17/$O$17 -> 1
D18: =D17/$K$17 -> 0.42625 | E18: =E17/$K$17 -> 0.2028125 | F18: =F17/$K$17 -> 0.079375 | G18: =G17/$K$17 -> 0.095625 | H18: =H17/$K$17 -> 0.12375 | I18: =I17/$K$17 -> 0.01625 | J18: =J17/$K$17 -> 0.0559375 | N18: =N17/O17 -> 0.15898658
B21: SALES FORCE | D21: TOTAL | F21: SALES FORCE | I21: SALES FORCE
F22: TERISI | G22: % | I22: VACANT | J22: %
B23: PRODUCT SPECIALIST (PS) | D23: ='DKI 1'!G51+'DKI 2'!G49+JABAR!G51+JATENG!G51+JATIM!G51+BALINUS!G51+SUMBAGSEL!G51+SUMBARI!G51+'SUMUT ACEH'!G51+SULAWESI!G37+KALIMANTAN!G51 -> 87 | F23: ='DKI 1'!H51+'DKI 2'!H49+JABAR!H51+JATENG!H51+JATIM!H51+BALINUS!H51+SUMBAGSEL!H51+SUMBARI!H51+'SUMUT ACEH'!H51+SULAWESI!H37+KALIMANTAN!H51 -> 66 | G23: =F23/D23 -> 0.75862069 | I23: =D23-F23 -> 21 | J23: =I23/D23 -> 0.24137931
B24: ACCOUNT EXECUTIVE (AE) | D24: ='DKI 1'!G52+'DKI 2'!G50+JABAR!G52+JATENG!G52+JATIM!G52+BALINUS!G52+SUMBAGSEL!G52+SUMBARI!G52+'SUMUT ACEH'!G52+SULAWESI!G38+KALIMANTAN!G52 -> 4 | F24: ='DKI 1'!H52+'DKI 2'!H50+JABAR!H52+JATENG!H52+JATIM!H52+BALINUS!H52+SUMBAGSEL!H52+SUMBARI!H52+'SUMUT ACEH'!H52+SULAWESI!H38+KALIMANTAN!H52 -> 1 | G24: =F24/D24 -> 0.25 | I24: =D24-F24 -> 3 | J24: =I24/D24 -> 0.75
B25: ACCOUNT MANAGER (AM) | D25: ='DKI 1'!G53+'DKI 2'!G51+JABAR!G53+JATENG!G53+JATIM!G53+BALINUS!G53+SUMBAGSEL!G53+SUMBARI!G53+'SUMUT ACEH'!G53+SULAWESI!G39+KALIMANTAN!G53 -> 8 | F25: ='DKI 1'!H53+'DKI 2'!H51+JABAR!H53+JATENG!H53+JATIM!H53+BALINUS!H53+SUMBAGSEL!H53+SUMBARI!H53+'SUMUT ACEH'!H53+SULAWESI!H39+KALIMANTAN!H53 -> 4 | G25: =F25/D25 -> 0.5 | I25: =D25-F25 -> 4 | J25: =I25/D25 -> 0.5
B26: DISTRICT MANAGER (DM) | D26: ='DKI 1'!G54+'DKI 2'!G52+JABAR!G54+JATENG!G54+JATIM!G54+BALINUS!G54+SUMBAGSEL!G54+SUMBARI!G54+'SUMUT ACEH'!G54+SULAWESI!G40+KALIMANTAN!G54 -> 34 | F26: ='DKI 1'!H54+'DKI 2'!H52+JABAR!H54+JATENG!H54+JATIM!H54+BALINUS!H54+SUMBAGSEL!H54+SUMBARI!H54+'SUMUT ACEH'!H54+SULAWESI!H40+KALIMANTAN!H54 -> 23 | G26: =F26/D26 -> 0.67647059 | I26: =D26-F26 -> 11 | J26: =I26/D26 -> 0.32352941
B27: REGIONAL SALES MANAGER (RSM) | D27: ='DKI 1'!G55+'DKI 2'!G53+JABAR!G55+JATENG!G55+JATIM!G55+BALINUS!G55+SUMBAGSEL!G55+SUMBARI!G55+'SUMUT ACEH'!G55+SULAWESI!G41+KALIMANTAN!G55 -> 6 | F27: ='DKI 1'!H55+'DKI 2'!H53+JABAR!H55+JATENG!H55+JATIM!H55+BALINUS!H55+SUMBAGSEL!H55+SUMBARI!H55+'SUMUT ACEH'!H55+SULAWESI!H41+KALIMANTAN!H55 -> 4 | G27: =F27/D27 -> 0.66666667 | I27: =D27-F27 -> 2 | J27: =I27/D27 -> 0.33333333
B28: BUSINESS CONTROL OFFICER (BCO) | D28: ='DKI 1'!G56+'DKI 2'!G54+JABAR!G56+JATENG!G56+JATIM!G56+BALINUS!G56+SUMBAGSEL!G56+SUMBARI!G56+'SUMUT ACEH'!G56+SULAWESI!G42+KALIMANTAN!G56 -> 11 | F28: ='DKI 1'!H56+'DKI 2'!H54+JABAR!H56+JATENG!H56+JATIM!H56+BALINUS!H56+SUMBAGSEL!H56+SUMBARI!H56+'SUMUT ACEH'!H56+SULAWESI!H42+KALIMANTAN!H56 -> 11 | G28: =F28/D28 -> 1 | I28: =D28-F28 -> 0 | J28: =I28/D28 -> 0
B29: GRAND TOTAL | D29: =SUM(D23:D28) -> 150 | F29: =SUM(F23:F28) -> 109 | G29: =F29/D29 -> 0.72666667 | I29: =SUM(I23:I28) -> 41 | J29: =I29/D29 -> 0.27333333

Sheet NAD
B2: JANGAN DI HAPUS
B3: DIVISI RAYON | C3: DIVISI INC | D3: STATUS SF
B5: UTM | C5: UTM | D5: PS TERISI
B6: SPM | C6: SPM | D6: PS VACANT
B7: PMT | C7: PMT | D7: AE TERISI
B8: PRM | C8: PRM | D8: AE VACANT
B9: PNC | C9: PNC | D9: DM TERISI
B10: COMBO UTM-SPM-PMT | C10: BCO | D10: DM VACANT
B11: COMBO UTM-SPM | D11: AM TERISI
B12: COMBO ALL DIV | D12: AM VACANT
B13: COMBO PRM-PNC | D13: RSM TERISI
D14: RSM VACANT
D15: BCO TERISI
D16: BCO VACANT
